<robot name="robot">
    <link name="base_link">
        <visual>
            <origin rpy="1.57 0 1.57" xyz="0 0 0" />
            <geometry>
                <mesh filename="package://PID/meshs/side.stl" scale="0.1 0.1 0.1"/>
            </geometry>
        </visual>
    </link>
    <link name="dc_roller">
        <visual>
            <origin rpy="1.57 0 0" xyz="0 0 0" />
            <geometry>
                <mesh filename="package://PID/meshs/dc_roll.stl" scale="0.1 0.1 0.1"/>
            </geometry>
        </visual>
    </link>
    <link name="dc_roller">
        <visual>
            <origin rpy="1.57 0 0" xyz="0 0 0" />
            <geometry>
                <mesh filename="package://PID/meshs/dc_roll.stl" scale="0.1 0.1 0.1"/>
            </geometry>
        </visual>
    </link>


    <joint name="j1" type="revolute">
        <parent link="base_link" />
        <child link="dc_roller" />
        <origin xyz="20 -5 3" rpy="0 0 0" />
        <axis xyz="0 1 0" />
        <limit lower="-3.14" upper="3.14" effort="20" velocity="5" />
    </joint>



</robot>